Traceback (most recent call last):
  File "<pyshell#10>", line 2, in <module>
Exception: His is a error message.
